Traceback (most recent call last):
  File "/home/lucas/.local/lib/python3.8/site-packages/jupyter_cache/executors/utils.py", line 58, in single_nb_execution
    executenb(
  File "/home/lucas/.local/lib/python3.8/site-packages/nbclient/client.py", line 1204, in execute
    return NotebookClient(nb=nb, resources=resources, km=km, **kwargs).execute()
  File "/home/lucas/.local/lib/python3.8/site-packages/nbclient/util.py", line 84, in wrapped
    return just_run(coro(*args, **kwargs))
  File "/home/lucas/.local/lib/python3.8/site-packages/nbclient/util.py", line 62, in just_run
    return loop.run_until_complete(coro)
  File "/usr/lib/python3.8/asyncio/base_events.py", line 616, in run_until_complete
    return future.result()
  File "/home/lucas/.local/lib/python3.8/site-packages/nbclient/client.py", line 663, in async_execute
    await self.async_execute_cell(
  File "/home/lucas/.local/lib/python3.8/site-packages/nbclient/client.py", line 965, in async_execute_cell
    await self._check_raise_for_error(cell, cell_index, exec_reply)
  File "/home/lucas/.local/lib/python3.8/site-packages/nbclient/client.py", line 862, in _check_raise_for_error
    raise CellExecutionError.from_cell_and_msg(cell, exec_reply_content)
nbclient.exceptions.CellExecutionError: An error occurred while executing the following cell:
------------------
dataset['xi_2'] = dataset['xi'] * dataset['xi']
dataset
------------------

[0;31m---------------------------------------------------------------------------[0m
[0;31mKeyError[0m                                  Traceback (most recent call last)
Input [0;32mIn [112][0m, in [0;36m<cell line: 1>[0;34m()[0m
[0;32m----> 1[0m dataset[[38;5;124m'[39m[38;5;124mxi_2[39m[38;5;124m'[39m] [38;5;241m=[39m [43mdataset[49m[43m[[49m[38;5;124;43m'[39;49m[38;5;124;43mxi[39;49m[38;5;124;43m'[39;49m[43m][49m [38;5;241m*[39m dataset[[38;5;124m'[39m[38;5;124mxi[39m[38;5;124m'[39m]
[1;32m      2[0m dataset

File [0;32m~/.local/lib/python3.8/site-packages/pandas/core/frame.py:3505[0m, in [0;36mDataFrame.__getitem__[0;34m(self, key)[0m
[1;32m   3503[0m [38;5;28;01mif[39;00m [38;5;28mself[39m[38;5;241m.[39mcolumns[38;5;241m.[39mnlevels [38;5;241m>[39m [38;5;241m1[39m:
[1;32m   3504[0m     [38;5;28;01mreturn[39;00m [38;5;28mself[39m[38;5;241m.[39m_getitem_multilevel(key)
[0;32m-> 3505[0m indexer [38;5;241m=[39m [38;5;28;43mself[39;49m[38;5;241;43m.[39;49m[43mcolumns[49m[38;5;241;43m.[39;49m[43mget_loc[49m[43m([49m[43mkey[49m[43m)[49m
[1;32m   3506[0m [38;5;28;01mif[39;00m is_integer(indexer):
[1;32m   3507[0m     indexer [38;5;241m=[39m [indexer]

File [0;32m~/.local/lib/python3.8/site-packages/pandas/core/indexes/range.py:389[0m, in [0;36mRangeIndex.get_loc[0;34m(self, key, method, tolerance)[0m
[1;32m    387[0m             [38;5;28;01mraise[39;00m [38;5;167;01mKeyError[39;00m(key) [38;5;28;01mfrom[39;00m[38;5;250m [39m[38;5;21;01merr[39;00m
[1;32m    388[0m     [38;5;28mself[39m[38;5;241m.[39m_check_indexing_error(key)
[0;32m--> 389[0m     [38;5;28;01mraise[39;00m [38;5;167;01mKeyError[39;00m(key)
[1;32m    390[0m [38;5;28;01mreturn[39;00m [38;5;28msuper[39m()[38;5;241m.[39mget_loc(key, method[38;5;241m=[39mmethod, tolerance[38;5;241m=[39mtolerance)

[0;31mKeyError[0m: 'xi'
KeyError: 'xi'

